<?xml version="1.0" ?>
<robot name="alphabot2">
  <link name="base_footprint"/>
  <joint name="base_joint" type="fixed">
    <parent link="base_footprint"/>
    <child link="base_link"/>
    <origin xyz="0.0 0.0 0.01" rpy="0 0 0"/>
  </joint>
  <link name="base_link">
    <visual>
      <origin xyz="0 0 0.0" rpy="0 0 0"/>
      <geometry>
        <mesh filename="package://ab2_description/meshes/dae/body.dae" scale="1.0 1.0 1.0"/>
      </geometry>
    </visual>
    <collision>
      <origin xyz="0.001 0 0.014" rpy="0 0 0"/>
      <geometry>
        <box size="0.14 0.14 0.05"/>
      </geometry>
    </collision>
    <inertial>
      <origin xyz="0.0 0.0 0.013"/>
      <mass value="0.50000000"/>
      <inertia ixx="0.00058889" ixy="0.00000000" ixz="-0.00000012" iyy="0.00054762" iyz="0.00000027" izz="0.00089218"/>
    </inertial>
  </link>
  <joint name="wheel_left_joint" type="continuous">
    <parent link="base_link"/>
    <child link="wheel_left_link"/>
    <origin xyz="-0.0425 0 0" rpy="0 0 0"/>
    <axis xyz="1 0 0"/>
  </joint>
  <link name="wheel_left_link">
    <visual>
      <origin xyz="0 0 0" rpy="0 0 0"/>
      <geometry>
        <mesh filename="package://ab2_description/meshes/dae/wheel.dae" scale="1.0 1.0 1.0"/>
      </geometry>
    </visual>
    <collision>
      <origin xyz="0 0 0" rpy="0 1.57 0"/>
      <geometry>
        <cylinder length="0.019" radius="0.021"/>
      </geometry>
    </collision>
    <inertial>
      <origin xyz="-0.00019604 -0.00018058 -0.00007497"/>
      <mass value="0.03000000"/>
      <inertia ixx="0.00000644" ixy="-0.00000000" ixz="-0.00000000" iyy="0.00000407" iyz="-0.00000000" izz="0.00000407"/>
    </inertial>
  </link>
  <joint name="wheel_right_joint" type="continuous">
    <parent link="base_link"/>
    <child link="wheel_right_link"/>
    <origin xyz="0.0425 0 0" rpy="0 3.14 0"/>
    <axis xyz="1 0 0"/>
  </joint>
  <link name="wheel_right_link">
    <visual>
      <origin xyz="0 0 0" rpy="0 0 0"/>
      <geometry>
        <mesh filename="package://ab2_description/meshes/dae/wheel.dae" scale="1.0 1.0 1.0"/>
      </geometry>
    </visual>
    <collision>
      <origin xyz="0 0 0" rpy="0 1.57 0"/>
      <geometry>
        <cylinder length="0.019" radius="0.021"/>
      </geometry>
    </collision>
    <inertial>
      <origin xyz="-0.00019604 -0.00018058 -0.00007497"/>
      <mass value="0.03000000"/>
      <inertia ixx="0.00000644" ixy="-0.00000000" ixz="-0.00000000" iyy="0.00000407" iyz="-0.00000000" izz="0.00000407"/>
    </inertial>        
  </link>
  <joint name="caster_back_joint" type="fixed">
    <parent link="base_link"/>
    <child link="caster_back_link"/>
    <origin xyz="0 -0.05 -0.016" rpy="0 0 0"/>
  </joint>
  <link name="caster_back_link">
    <collision>
      <origin xyz="0 0 0" rpy="0 0 0"/>
      <geometry>
        <box size="0.01 0.01 0.01"/>
      </geometry>
    </collision>
  </link>
  <joint name="caster_front_joint" type="fixed">
    <parent link="base_link"/>
    <child link="caster_front_link"/>
    <origin xyz="0 0.05 -0.016" rpy="0 0 0"/>
  </joint>
  <link name="caster_front_link">
    <collision>
      <origin xyz="0 0 0" rpy="0 0 0"/>
      <geometry>
        <box size="0.01 0.01 0.01"/>
      </geometry>
    </collision>
  </link>
</robot>